[0m20:50:50.627636 [debug] [MainThread]: Sending event: {'category': 'dbt', 'action': 'invocation', 'label': 'start', 'context': [<snowplow_tracker.self_describing_json.SelfDescribingJson object at 0x000001D38DA22F90>, <snowplow_tracker.self_describing_json.SelfDescribingJson object at 0x000001D38E9C7110>, <snowplow_tracker.self_describing_json.SelfDescribingJson object at 0x000001D38E9C7250>]}


============================== 20:50:50.631117 | 988673c2-7e4a-4075-a4c1-9a1df5492405 ==============================
[0m20:50:50.631117 [info ] [MainThread]: Running with dbt=1.9.3
[0m20:50:50.631603 [debug] [MainThread]: running dbt with arguments {'printer_width': '80', 'indirect_selection': 'eager', 'log_cache_events': 'False', 'write_json': 'True', 'partial_parse': 'True', 'cache_selected_only': 'False', 'warn_error': 'None', 'debug': 'False', 'version_check': 'True', 'log_path': 'logs', 'fail_fast': 'False', 'profiles_dir': 'C:\\Users\\diogo\\.dbt', 'use_colors': 'True', 'use_experimental_parser': 'False', 'empty': 'None', 'quiet': 'False', 'no_print': 'None', 'warn_error_options': 'WarnErrorOptions(include=[], exclude=[])', 'introspect': 'True', 'static_parser': 'True', 'invocation_command': 'dbt ', 'target_path': 'None', 'log_format': 'default', 'send_anonymous_usage_stats': 'True'}
[0m20:50:50.632261 [error] [MainThread]: Encountered an error:
Runtime Error
  No dbt_project.yml found at expected path c:\Users\diogo\Downloads\GitHub\jornada_de_dados\5-dbtbigquery\datawarehouse\dbt_project.yml
  Verify that each entry within packages.yml (and their transitive dependencies) contains a file named dbt_project.yml

[0m20:50:50.632916 [debug] [MainThread]: Command `cli deps` failed at 20:50:50.632784 after 0.10 seconds
[0m20:50:50.633224 [debug] [MainThread]: Sending event: {'category': 'dbt', 'action': 'invocation', 'label': 'end', 'context': [<snowplow_tracker.self_describing_json.SelfDescribingJson object at 0x000001D38EAA3820>, <snowplow_tracker.self_describing_json.SelfDescribingJson object at 0x000001D38EAED7F0>, <snowplow_tracker.self_describing_json.SelfDescribingJson object at 0x000001D38EA3ABE0>]}
[0m20:50:50.633541 [debug] [MainThread]: Flushing usage events
[0m20:50:51.295553 [debug] [MainThread]: An error was encountered while trying to flush usage events
[0m18:47:23.192136 [debug] [MainThread]: Sending event: {'category': 'dbt', 'action': 'invocation', 'label': 'start', 'context': [<snowplow_tracker.self_describing_json.SelfDescribingJson object at 0x000001EA3EE72F90>, <snowplow_tracker.self_describing_json.SelfDescribingJson object at 0x000001EA3FE2B110>, <snowplow_tracker.self_describing_json.SelfDescribingJson object at 0x000001EA3FE2B250>]}


============================== 18:47:23.195794 | 0ddd81f3-6d14-4ba8-993f-d08e281a8970 ==============================
[0m18:47:23.195794 [info ] [MainThread]: Running with dbt=1.9.3
[0m18:47:23.196306 [debug] [MainThread]: running dbt with arguments {'printer_width': '80', 'indirect_selection': 'eager', 'log_cache_events': 'False', 'write_json': 'True', 'partial_parse': 'True', 'cache_selected_only': 'False', 'profiles_dir': 'C:\\Users\\diogo\\.dbt', 'debug': 'False', 'fail_fast': 'False', 'log_path': 'logs', 'version_check': 'True', 'warn_error': 'None', 'use_colors': 'True', 'use_experimental_parser': 'False', 'empty': 'None', 'quiet': 'False', 'no_print': 'None', 'log_format': 'default', 'static_parser': 'True', 'invocation_command': 'dbt ', 'warn_error_options': 'WarnErrorOptions(include=[], exclude=[])', 'target_path': 'None', 'introspect': 'True', 'send_anonymous_usage_stats': 'True'}
[0m18:47:23.196881 [error] [MainThread]: Encountered an error:
Runtime Error
  No dbt_project.yml found at expected path c:\Users\diogo\Downloads\GitHub\jornada_de_dados\5-dbtbigquery\dbt_packages\dbt-utils-1.1.1\dbt_project.yml
  Verify that each entry within packages.yml (and their transitive dependencies) contains a file named dbt_project.yml

[0m18:47:23.197531 [debug] [MainThread]: Command `cli deps` failed at 18:47:23.197417 after 0.15 seconds
[0m18:47:23.197903 [debug] [MainThread]: Sending event: {'category': 'dbt', 'action': 'invocation', 'label': 'end', 'context': [<snowplow_tracker.self_describing_json.SelfDescribingJson object at 0x000001EA3FEFF820>, <snowplow_tracker.self_describing_json.SelfDescribingJson object at 0x000001EA3FF4D7F0>, <snowplow_tracker.self_describing_json.SelfDescribingJson object at 0x000001EA3FE9EBE0>]}
[0m18:47:23.198250 [debug] [MainThread]: Flushing usage events
[0m18:47:23.755762 [debug] [MainThread]: An error was encountered while trying to flush usage events
[0m18:47:24.612925 [debug] [MainThread]: Sending event: {'category': 'dbt', 'action': 'invocation', 'label': 'start', 'context': [<snowplow_tracker.self_describing_json.SelfDescribingJson object at 0x0000019EB3702F90>, <snowplow_tracker.self_describing_json.SelfDescribingJson object at 0x0000019EB46B7110>, <snowplow_tracker.self_describing_json.SelfDescribingJson object at 0x0000019EB46B7250>]}


============================== 18:47:24.616493 | 4ee9b3cc-d0f7-4d9f-bae4-6cf194f566c4 ==============================
[0m18:47:24.616493 [info ] [MainThread]: Running with dbt=1.9.3
[0m18:47:24.617108 [debug] [MainThread]: running dbt with arguments {'printer_width': '80', 'indirect_selection': 'eager', 'log_cache_events': 'False', 'write_json': 'True', 'partial_parse': 'True', 'cache_selected_only': 'False', 'warn_error': 'None', 'debug': 'False', 'fail_fast': 'False', 'log_path': 'logs', 'profiles_dir': 'C:\\Users\\diogo\\.dbt', 'version_check': 'True', 'use_colors': 'True', 'use_experimental_parser': 'False', 'no_print': 'None', 'quiet': 'False', 'empty': 'None', 'log_format': 'default', 'introspect': 'True', 'static_parser': 'True', 'invocation_command': 'dbt ', 'target_path': 'None', 'warn_error_options': 'WarnErrorOptions(include=[], exclude=[])', 'send_anonymous_usage_stats': 'True'}
[0m18:47:24.617985 [error] [MainThread]: Encountered an error:
Runtime Error
  No dbt_project.yml found at expected path c:\Users\diogo\Downloads\GitHub\jornada_de_dados\5-dbtbigquery\dbt_packages\dbt-utils-1.1.1\dbt_project.yml
  Verify that each entry within packages.yml (and their transitive dependencies) contains a file named dbt_project.yml

[0m18:47:24.618990 [debug] [MainThread]: Command `cli deps` failed at 18:47:24.618815 after 0.12 seconds
[0m18:47:24.619382 [debug] [MainThread]: Sending event: {'category': 'dbt', 'action': 'invocation', 'label': 'end', 'context': [<snowplow_tracker.self_describing_json.SelfDescribingJson object at 0x0000019EB478F820>, <snowplow_tracker.self_describing_json.SelfDescribingJson object at 0x0000019EB47E17F0>, <snowplow_tracker.self_describing_json.SelfDescribingJson object at 0x0000019EB472ABE0>]}
[0m18:47:24.619727 [debug] [MainThread]: Flushing usage events
[0m18:47:25.196414 [debug] [MainThread]: An error was encountered while trying to flush usage events
